Workbook

Sheet Data
A1: ID | B1: Start time | C1: Completion time | D1: Email | E1: Name | F1: BHR Name | G1: BHR Employee ID | H1: Date of Connect | I1: Engagement Type | J1: IBU/Practice/Location | K1: Mention your location {Ex. Noida} | L1: PRACTICE CODE (As per head count report) {Ex. DEA-D-2007} | M1: Band | N1: Engagement Mode | O1: Service Line | P1: EMPLOYEE IBU CODE (As per head count report) {Ex. DEA-D-4031} | Q1: PROJECT DESCRIPTION (As per head count report) {If Mixed then list down all the Project name/Practice/ SL} | R1: LSA Connect (In detail) | S1: Exclusive Award Ceremony (Not part of Townhall) (In detail) | T1: Cadence Connect | U1: CARES Framework | V1: Career | W1: Alignment | X1: Recognition | Y1: Empowerment | Z1: Strive | AA1: Townhall - Coverage | AB1: Townhall - Key Insight | AC1: Townhall - Action Plan | AD1: SL Induction - Coverage | AE1: SL Induction - Key Insight | AF1: SL Induction - Action Plan | AG1: Business Wait Connect - Coverage | AH1: Business Wait Connect - Key Insight | AI1: Business Wait Connect - Action Plan | AJ1: ELTP Connect (Practice Level) - Coverage | AK1: ELTP Connect (Practice Level) - Key Insight | AL1: ELTP Connect (Practice Level) - Action Plan | AM1: ELTP Connect (<6m) - Coverage | AN1: ELTP Connect (<6m) - Key Insight | AO1: ELTP Connect (<6m) - Action Plan | AP1: ELTP Connect (6-12m) - Coverage | AQ1: ELTP Connect (6-12m) - Key Insight | AR1: ELTP Connect (6-12m) - Action Plan | AS1: ELTP Connect (12-24m) - Coverage | AT1: ELTP Connect (12-24m) - Key Insight | AU1: ELTP Connect (12-24m) - Action Plan | AV1: HR Connect (Project Wise) - Coverage | AW1: HR Connect (Project Wise) - Key Insights | AX1: HR Connect (Project Wise) - Action Plan | AY1: HR Connect (General) - Coverage | AZ1: HR Connect (General) - Key Insights | BA1: HR Connect (General) - Action Plan | BB1: Top Talent Connect - Coverage | BC1: Top Talent Connect - Key Insights | BD1: Top Talent Connect - Action Plan | BE1: Top Talent FGD Connect - Coverage | BF1: Top Talent FGD Connect - Key Insights | BG1: Top Talent FGD Connect - Action Plan | BH1: New Joiner Connect (7 Days) - Coverage | BI1: New Joiner Connect (7 Days) - Key Insights | BJ1: New Joiner Connect (7 Days) - Action Plan | BK1: New Joiner Connect (30 Days) - Coverage | BL1: New Joiner Connect (30 Days) - Key Insights | BM1: New Joiner Connect (30 Days) - Action Plan | BN1: New Joiner Connect (60 Days) - Coverage | BO1: New Joiner Connect (60 Days) - Key Insights | BP1: New Joiner Connect (60 Days) - Action Plan | BQ1: New Joiner Connect (90 Days) - Coverage | BR1: New Joiner Connect (90 Days) - Key Insights | BS1: New Joiner Connect (90 Days) - Action Plan | BT1: ML Returnee Connect - Coverage | BU1: ML Returnee Connect - Key Insights | BV1: ML Returnee Connect - Action Plan | BW1: Skip Meeting - Coverage | BX1: Skip Meeting - Key Insights | BY1: Skip Meeting - Action Plan | BZ1: Women Associate Connect - Coverage | CA1: Women Associate Connect - Key Insights | CB1: Women Associate Connect - Action Plan | CC1: Band Specific FGD Connect - Coverage | CD1: Band Specific FGD Connect - Key Insights | CE1: Band Specific FGD Connect - Action Plan | CF1: Leadership Connect - Coverage | CG1: Leadership Connect - Key Insights | CH1: Leadership Connect - Action Plan | CI1: Josh (Fun Engagements) - Coverage | CJ1: Josh (Fun Engagements) - Key Insights | CK1: Josh (Fun Engagements) - Action Plan | CL1: Wellness Session - Coverage | CM1: Wellness Session - Key Insights | CN1: Wellness Session - Action Plan | CO1: ISR Activity - Coverage | CP1: ISR Activity - Key Insights | CQ1: ISR Activity - Action Plan | CR1: Overall Sentiment | CS1: Action Owner | CT1: Engagement related Queries | CU1: Severity | CV1: Status | CW1: IBU Level Connect (Points discussed if any) | CX1: SL Level Connect (Points discussed if any) | CY1: Practice Level Connect ( (Points discussed if any)
A2: 1 | B2: 46150.506 | C2: 46150.523 | D2: AK216739@techmahindra.com | E2: Anvi Konda | F2: Liam Chaudry | G2: 216739 | H2: 46142 | I2: Large Connect | J2: IBU Specific Connect | K2: Gudivada | L2: DEA-D-2003 | M2: MIX | N2: Virtual | O2: DEA Service Line | P2: DEA-D-2004 | Q2: Practice | U2: Alignment | W2: ML Returnee Connect | BT2: Review of ongoing concerns; | BU2: No major concerns raised;Minor process related queries; | BV2: NA;Continue regular check-ins; | CR2: Neutral | CS2: No specific Action, Issue addressed in meeting; | CT2: NA | CU2: Moderate | CV2: Closed
A3: 2 | B3: 46110.807 | C3: 46110.828 | D3: GK145561@techmahindra.com | E3: Girik Kamdar | F3: Girik Kamdar | G3: 145561 | H3: 46093 | I3: Large Connect | J3: Location Specific Connect | K3: Dibrugarh | L3: DEA-D-4021 | M3: U | N3: Virtual | O3: CIS Service Line | P3: DEA-D-4031 | Q3: EY Project | U3: Alignment | W3: Townhall | AA3: Business & Strategy Clarity;Career Visibility & Skill Roadmap;AI/future Readiness Messaging Is High-level; | AB3: Associates are unsure how unit goals translate into day-to-day delivery expectations; | AC3: Capture workload hotspots and review with delivery leads for rebalancing;NA; | CR3: Neutral | CS3: No specific Action, Issue addressed in meeting; | CU3: Moderate | CV3: Open
A4: 3 | B4: 46143.679 | C4: 46143.697 | D4: OK356702@techmahindra.com | E4: Oni Kannan | F4: Oni Kannan | G4: 356702 | H4: 46131 | I4: Large Connect | J4: Location Specific Connect | K4: Hyderabad | L4: DEA-D-4026 | M4: U | N4: In-person-Tech M | O4: DEA Service Line | P4: CIS D 2001 | Q4: Kimberly Clark | U4: Alignment | W4: SL Induction | AD4: Visibility on Allocation & Demand; | AE4: Associates lack clarity on practice goals and IBU priorities;HR/WFM/Training updates not actionable; | AF4: TLS SPOC had cleared all the queries w.r.t learning;Provide FAQs, guides, refresher sessions; | CR4: Positive | CS4: No specific Action, Issue addressed in meeting; | CT4: Team was contented with the fun connect as it was a nice short break from work and the whole account was able to connect virtually | CU4: Moderate | CV4: Closed
A5: 4 | B5: 46115.788 | C5: 46115.793 | D5: AD634277@techmahindra.com | E5: Abeer Dutta | F5: Abeer Dutta | G5: 634277 | H5: 46114 | I5: Location-Offshore | J5: IBU Specific Connect | K5: Mau | L5: NGS-D-2004 | M5: MIX | N5: Virtual | O5: DEA Service Line | P5: DEA-D-4022 | Q5: Rating Calibration call with IBU Head | U5: Alignment | W5: ML Returnee Connect | BT5: General wellbeing check-in; | BU5: Associates are settling in well;NA; | BV5: Share update with relevant stakeholder;Continue regular check-ins; | CR5: Positive | CS5: WFM;Delivery; | CT5: No response on IJP applied on Rapid | CU5: High | CV5: In-progress
A6: 5 | B6: 46084.515 | C6: 46084.532 | D6: GC632323@techmahindra.com | E6: Gayathri Chaudry | F6: Gayathri Chaudry | G6: 632323 | H6: 46080 | I6: FGD | J6: IBU Specific Connect | K6: Bengaluru | L6: DEA-D-4026 | M6: MIX | N6: Virtual | O6: DEA Service Line | P6: NGS-D-4037 | Q6: Keysight | U6: Alignment | W6: HR Connect (General) | AY6: Connect for recognition;Clarity On Role-based Learning Expectations;On Hybrid/WFO Rules And Monthly Compliance Expectations; | AZ6: Discussed on how to simply WFH exception requests and about various projects;NA; | BA6: Share role-based learning pathways and recommended certifications; | CR6: Positive | CS6: Delivery; | CT6: NA | CU6: Moderate | CV6: Closed
A7: 6 | B7: 46050.726 | C7: 46050.735 | D7: JP518373@techmahindra.com | E7: Jagrati Padmanabhan | F7: Jagrati Padmanabhan | G7: 518373 | H7: 46030 | I7: FGD | J7: Location Specific Connect | K7: Hyderabad | L7: DEA-D-2026 | M7: MIX | N7: Virtual | O7: DEA Service Line | P7: DEA-D-4032 | Q7: GE | U7: Career | V7: ELTP Connect (6-12m) | AP7: Business Context & Org Awareness; | AQ7: Feedback is irregular or not tied to a rubric; | AR7: Run fortnightly utilization reviews with WFM + delivery owners to rebalance work; | CR7: Positive | CS7: No specific Action, Issue addressed in meeting; | CT7: Need budget clarity | CU7: Low | CV7: Closed
A8: 7 | B8: 46143.99 | C8: 46144.003 | D8: TY946721@techmahindra.com | E8: Tripti Yadav | F8: Tripti Yadav | G8: 946721 | H8: 46140 | I8: Large Connect | J8: IBU Specific Connect | K8: Pune | L8: DEA- D-4023, DEA-D-4024, DEA-D-4025 | M8: MIX | N8: In-person-Client Location | O8: DEA Service Line | P8: DEA-D-4018 | Q8: TMC-D-1001- TMC ALL | U8: Alignment | W8: SL Induction | AD8: Business & Practice Awareness; | AE8: Low interaction and hesitation in raising questions; | AF8: Create consistent onboarding framework across practice;Provide FAQs, guides, refresher sessions; | CR8: Positive | CS8: No specific Action, Issue addressed in meeting; | CT8: Allocation related queries and opportunities | CU8: Moderate | CV8: In-progress | CY8: Practice level priorities and bench status reviewed.
A9: 8 | B9: 46056.582 | C9: 46056.583 | D9: FM197793@techmahindra.com | E9: Farhan Memon | F9: Farhan Memon | G9: 197793 | H9: 46049 | I9: Large Connect | J9: IBU Specific Connect | K9: Gangtok | L9: IIGA | M9: E | N9: Virtual | O9: DEA Service Line | P9: DEA-D-4016 | Q9: IBU Head of SNOW Europe | U9: Empowerment | Y9: Band Specific FGD Connect | CC9: Clarity on expectations;Review of ongoing concerns; | CD9: No major concerns raised; | CE9: Continue regular check-ins;NA; | CR9: Positive | CS9: No specific Action, Issue addressed in meeting; | CT9: All was resolved | CU9: Moderate | CV9: Closed | CW9: SALESFORCE PRACTICE
A10: 9 | B10: 46068.895 | C10: 46068.898 | D10: CK992697@techmahindra.com | E10: Chakradev Kari | F10: Chakradev Kari | G10: 992697 | H10: 46049 | I10: Large Connect | J10: Location Specific Connect | K10: Hyderabad | L10: DEA- D-4023, DEA-D-4024, DEA-D-4025 | M10: MIX | N10: Virtual | O10: DEA Service Line | P10: DEA-D-4026 | Q10: Kimberly Clark | U10: Empowerment | Y10: Women Associate Connect | BZ10: Recognition & Visibility;Grievance/speak-up Clarity;Empathy And Communication; | CA10: Need empathy and communication;Grievance/speak-up clarity; | CB10: There werenot much queries;Promote DEI initiatives; | CR10: Mixed | CS10: HRBP;Delivery; | CT10: NA | CU10: Low | CV10: Closed
A11: 10 | B11: 46174.899 | C11: 46174.908 | D11: VC172132@techmahindra.com | E11: Viraj Chaudhuri | F11: Viraj Chaudhuri | G11: 172132 | H11: 46163 | I11: FGD | J11: IBU Specific Connect | K11: Hyderbad | L11: all | M11: MIX | N11: In-person-Tech M | O11: DEA Service Line | P11: DIG-D-4001, DIG-D-4005, DIG-D-4007 | Q11: DEA BLR (Women Associates) | U11: Empowerment | Y11: Women Associate Connect | BZ11: Career Support & Sponsorship;Work-Life Balance & Flexibility; | CA11: Inclusive team practices; | CB11: Promote DEI initiatives;Reinforce speak-up channels; | CR11: Positive | CS11: Delivery; | CT11: RTO management and Bench | CU11: Low | CV11: In-progress
A12: 11 | B12: 46103.179 | C12: 46103.187 | D12: JG146228@techmahindra.com | E12: Janya Gaba | F12: Isha Kadakia | G12: 146228 | H12: 46099 | I12: 1:1 | J12: IBU Specific Connect | K12: PUNE | L12: DAI-D-2005 | M12: MIX | N12: Mix (Virtual & In-person) | O12: DEA Service Line | P12: COM D 4018 | Q12: SAP | U12: Career | V12: Top Talent FGD Connect | BE12: Review of ongoing concerns;Feedback on recent processes;Clarity on expectations; | BF12: NA; | BG12: Monitor and follow up in next cycle;NA; | CR12: Neutral | CS12: No specific Action, Issue addressed in meeting; | CU12: Low | CV12: In-progress
A13: 12 | B13: 46156.119 | C13: 46156.126 | D13: OW270395@techmahindra.com | E13: Onveer Walla | F13: Onveer Walla | G13: 270395 | H13: 46151 | I13: Location-Offshore | J13: IBU Specific Connect | K13: Kolkata | L13: NGS-D-2004 | M13: U | N13: In-person-Tech M | O13: CIS Service Line | P13: DEA-D-4001 | Q13: DIG-D-4005, DIG-D-4008, DIG-D-4009 | U13: Empowerment | Y13: Leadership Connect | CF13: AI Session;Review Cadence; | CG13: Need AI/skill readiness; | CH13: Publish budget guidelines;Identify hotspots; | CR13: Neutral | CS13: Delivery;HRBP; | CT13: NA | CU13: Moderate | CV13: Closed
A14: 13 | B14: 46166.878 | C14: 46166.892 | D14: TR519093@techmahindra.com | E14: Turvi Raghavan | F14: Turvi Raghavan | G14: 519093 | H14: 46149 | I14: FGD | J14: IBU Specific Connect | K14: Hyderbad | L14: DEA-D-2006 | M14: MIX | N14: In-person-Client Location | O14: DEA Service Line | P14: DEA-D-4040 | Q14: New Joiner Connect - 60 days | U14: Alignment | W14: New Joiner Connect (30 Days) | BK14: Role Expectation Clarity;Initial Engagement Level; | BL14: Most of the associates are undergoing trainings as there are FCTP's;Delay or lack of clarity in project onboarding; | BM14: Define timeline for project allocation (max 0 days);Ensure weekly : connect with manager; | CR14: Positive | CS14: HRBP;Delivery; | CT14: NA | CU14: Low | CV14: Closed
A15: 14 | B15: 46083.069 | C15: 46083.078 | D15: EB753425@techmahindra.com | E15: Ekta Bhalla | F15: Ekta Bhalla | G15: 753425 | H15: 46080 | I15: Floor Connect | J15: IBU Specific Connect | K15: PUNE | L15: DEA-D-4026 | M15: MIX | N15: Virtual | O15: DEA Service Line | P15: DEA-D-4019 | Q15: Scotia | U15: Empowerment | Y15: Women Associate Connect | BZ15: Learning & Skill Building;Grievance/speak-up Clarity;Inclusive Team Practices; | CA15: Inclusive team practices; | CB15: Promote DEI initiatives;There werenot much queries; | CR15: Neutral | CS15: Delivery; | CU15: Low | CV15: Closed
A16: 15 | B16: 46075.604 | C16: 46075.621 | D16: DR188914@techmahindra.com | E16: Diya Rattan | F16: Diya Rattan | G16: 188914 | H16: 46055 | I16: 1:1 | J16: IBU Specific Connect | K16: Hyderabad | L16: DEA-D-4021 | M16: MIX | N16: Virtual | O16: DEA Service Line | P16: DEA-D-2007 | Q16: Oracle HCM – UKG & Workday | U16: Alignment | W16: SL Induction | AD16: HR / WFM / Training Communication Effectiveness;Business & Practice Awareness; | AE16: HR/WFM/Training updates not actionable;NA; | AF16: Create consistent onboarding framework across practice; | CR16: Neutral | CS16: No specific Action, Issue addressed in meeting; | CT16: Bench guidelines are explained | CU16: Low | CV16: Closed
A17: 16 | B17: 46082.666 | C17: 46082.681 | D17: DK361303@techmahindra.com | E17: Divya Kala | F17: Divya Kala | G17: 361303 | H17: 46079 | I17: FGD | J17: Practice Specific Connect (Across IBU) | K17: Kolkata | L17: NWS-D-1001 | M17: MIX | N17: In-person-Tech M | O17: DEA Service Line | P17: NGS-D-4037 | Q17: SAP HLS | U17: Alignment | W17: HR Connect (Project Wise) | AV17: Timesheet Submission/approval Process Inconsistencies Create;Workload & Work-Life Balance;Manager Support & Local Leadership Effectiveness; | AW17: Timesheet submission/approval process inconsistencies create compliance risk; | AX17: Share project-specific policy FAQ (WFO, exceptions, leave, timesheet);Implement monthly recognition cadence (kudos, spotlight, customer praise); | CR17: Positive | CS17: No specific Action, Issue addressed in meeting; | CT17: NA | CU17: Moderate | CV17: Closed
A18: 17 | B18: 46153.429 | C18: 46153.439 | D18: TD827659@techmahindra.com | E18: Tara Dhar | F18: Tara Dhar | G18: 827659 | H18: 46147 | I18: Large Connect | J18: IBU Specific Connect | K18: PUNE | L18: DEA- D-4023, DEA-D-4024, DEA-D-4025 | M18: MIX | N18: Virtual | O18: NGS Service Line | P18: DEA-D-4032 | Q18: Suncorp Bank | U18: Career | V18: ELTP Connect (12-24m) | AS18: Internal Mobility / Rotation Opportunities;Recognition & Visibility of Growth;Career Progression & Next-Level Readiness; | AT18: Rotation/mobility interest is high but process and eligibility are unclear;na; | AU18: Highlight ELTP success stories + learning milestones in leadership forums/townhalls;Run structured mobility/rotation sessions with examples and process FAQs; | CR18: Positive | CS18: No specific Action, Issue addressed in meeting; | CU18: Low | CV18: Closed
A19: 18 | B19: 46082.144 | C19: 46082.16 | D19: AS660069@techmahindra.com | E19: Adya Sangha | F19: Janaki Kanda | G19: 660069 | H19: 46070 | I19: 1:1 | J19: Practice Specific Connect (Across IBU) | K19: Danapur | L19: NGS-D-2004 | M19: MIX | N19: Virtual | O19: DEA Service Line | P19: DEA-D-4016 | Q19: Location connect with DEA team. AI session by Natesh. | U19: Alignment | W19: New Joiner Connect (30 Days) | BK19: Project Allocation Clarity;Manager Connect Effectiveness; | BL19: Difficulty in understanding tools/processes;Associates undergoing project training; | BM19: Define timeline for project allocation (max 0 days);NA; | CR19: Negative | CS19: No specific Action, Issue addressed in meeting; | CT19: the associates had doubts related to the RTO guidelines and seat allocations | CU19: Moderate | CV19: Closed
A20: 19 | B20: 46123.875 | C20: 46123.882 | D20: ID232352@techmahindra.com | E20: Imaran Dua | F20: Imaran Dua | G20: 232352 | H20: 46120 | I20: 1:1 | J20: IBU Specific Connect | K20: Kolkata | L20: DEA-D-2006 | M20: MIX | N20: Mix (Virtual & In-person) | O20: DIG Vertical | P20: MFG-D-4003 | Q20: DIG-D-4005, DIG-D-4008, DIG-D-4009 | U20: Strive | Z20: Josh (Fun Engagements) | CI20: General wellbeing check-in;Discussion on team dynamics;Clarity on expectations; | CJ20: Minor process related queries;No major concerns raised; | CK20: No specific action required; | CR20: Neutral | CS20: Delivery; | CT20: NA | CU20: High | CV20: Closed | CX20: Discussed general SL level updates and priorities.
A21: 20 | B21: 46148.32 | C21: 46148.329 | D21: DR658623@techmahindra.com | E21: Devansh Rajan | F21: Devansh Rajan | G21: 658623 | H21: 46137 | I21: Large Connect | J21: Practice Specific Connect (Across IBU) | K21: Kavali | L21: NGS-D-2004 | M21: U | N21: Virtual | O21: Network Services Service Line | P21: DIG-D-1001 | Q21: OPTUS | U21: Alignment | W21: New Joiner Connect (60 Days) | BN21: Workload Management; | BO21: Skill gaps becoming visible during execution;The associates had questions around WFH and leaves.; | BP21: Mandate structured monthly feedback from manager;The associates had queries mainly related to WFH and leaves.; | CR21: Neutral | CS21: Delivery; | CU21: High | CV21: Closed
A22: 21 | B22: 46215.61 | C22: 46215.628 | D22: AC497399@techmahindra.com | E22: Advay Contractor | F22: Advay Contractor | G22: 497399 | H22: 46200 | I22: Location-Offshore | J22: IBU Specific Connect | K22: Mau | L22: DEA-D-40026 | M22: MIX | N22: In-person-Tech M | O22: DIG Vertical | P22: DEA-D-4001 | Q22: SAP MEA | U22: Career | V22: Top Talent Connect | BB22: Clarity on Org Changes & Priorities; | BC22: No hike/VP alignment with performance; | BD22: Run quarterly nominations; | CR22: Positive | CS22: HRBP; | CU22: Moderate | CV22: Closed
A23: 22 | B23: 46054.159 | C23: 46054.173 | D23: NS656711@techmahindra.com | E23: Nakul Setty | F23: Nakul Setty | G23: 656711 | H23: 46037 | I23: FGD | J23: Practice Specific Connect (Across IBU) | K23: Firozabad | L23: DEA-D-40026 | M23: MIX | N23: In-person-Tech M | O23: DEA Service Line | P23: IFS | Q23: SALESFORCE PRACTICE | U23: Empowerment | Y23: Women Associate Connect | BZ23: Empathy And Communication; | CA23: Inclusive team practices;Need flexible arrangements during caregiving; | CB23: Leadership acknowledgment;There werenot much queries; | CR23: Positive | CS23: No specific Action, Issue addressed in meeting; | CT23: NA | CU23: Moderate | CV23: Closed
A24: 23 | B24: 46211.187 | C24: 46211.204 | D24: YC889359@techmahindra.com | E24: Yashica Cherian | F24: Yashica Cherian | G24: 889359 | H24: 46211 | I24: 1:1 | J24: IBU Specific Connect | K24: Chennai | L24: DEA- D-4023, DEA-D-4024, DEA-D-4025 | M24: MIX | N24: In-person-Tech M | O24: DEA Service Line | P24: CIS D 4001,4004,4025,4026 | Q24: NGS-D-4037 | U24: Alignment | W24: Townhall | AA24: Business & Strategy Clarity; | AB24: Associates are unsure how unit goals translate into day-to-day delivery expectations;associates seek practical relevance; | AC24: Publish role-based learning paths (beginner/intermediate/advanced) with links; | CR24: Neutral | CS24: Delivery; | CT24: No Projects for New Joiners in Bench | CU24: Low | CV24: Closed | CW24: Discussed regarding MCares Dissemination, attrition and diversity. IBU Head was happy with progress made so far. | CY24: Practice level priorities and bench status reviewed.
A25: 24 | B25: 46192.685 | C25: 46192.694 | D25: YI696251@techmahindra.com | E25: Yashica Issac | F25: Yashica Issac | G25: 696251 | H25: 46173 | I25: Leadership Connect | J25: IBU Specific Connect | K25: Hyderabad | L25: DEA-D-40026 | M25: MIX | N25: Virtual | O25: DEA Service Line | P25: CIS D 4001,4004,4025,4026 | Q25: DIG-D-4005, DIG-D-4008, DIG-D-4009 | U25: Career | V25: ELTP Connect (Practice Level) | AJ25: Engagement & Motivation Across Stages;Career Clarity & Growth Continuity;Allocation & Deployment Transparency; | AK25: Inconsistent visibility on allocation timelines and decision-making creates confusion across all ELTP groups; | AL25: Work with work force management and delivery closely to ensure the ELTP associates are mapped to projects once their trainings are completed;Introduce ELTP engagement framework by stage: 0–6M → onboarding support, 6–M → performance alignment, –M → growth & retention; | CR25: Positive | CS25: No specific Action, Issue addressed in meeting; | CT25: NA | CU25: Low | CV25: In-progress
A26: 25 | B26: 46061.694 | C26: 46061.699 | D26: AN378535@techmahindra.com | E26: Aadi Naik | F26: Aadi Naik | G26: 378535 | H26: 46059 | I26: Large Connect | J26: Practice Specific Connect (Across IBU) | K26: Hyderbad | L26: NWS-D-1001 | M26: MIX | N26: In-person-Tech M | O26: DIG Vertical | P26: DEA-D-4001 | Q26: Practice | U26: Alignment | W26: New Joiner Connect (90 Days) | BQ26: Career Path Visibility; | BR26: seat allocation;Lack of awareness of internal opportunities; | BS26: Align role expectations vs aspiration through discussion;shared CS SPOC details; | CR26: Positive | CS26: Delivery; | CT26: aNA | CU26: High | CV26: Open
A27: 26 | B27: 46122.979 | C27: 46122.998 | D27: JM283700@techmahindra.com | E27: Janani Mohanty | F27: Janani Mohanty | G27: 283700 | H27: 46102 | I27: FGD | J27: IBU Specific Connect | K27: PUNE | L27: TMC-D-1001 | M27: P | N27: Virtual | O27: DEA Service Line | P27: DEA-D-4009 | Q27: Scotia | U27: Career | V27: Top Talent Connect | BB27: For Role Rotation (PM/PGM/architect);Recognition Equity & Visibility; | BC27: No hike/VP alignment with performance; | BD27: Not happy with no hike; | CR27: Positive | CS27: No specific Action, Issue addressed in meeting; | CT27: NA | CU27: High | CV27: In-progress
A28: 27 | B28: 46077.503 | C28: 46077.506 | D28: FC296694@techmahindra.com | E28: Farhan Chada | F28: Farhan Chada | G28: 296694 | H28: 46058 | I28: Floor Connect | J28: IBU Specific Connect | K28: Hyderabad | L28: DEA-D-40026 | M28: MIX | N28: Mix (Virtual & In-person) | O28: DEA Service Line | P28: DIG-D-4005 | Q28: Paragon | U28: Career | V28: ELTP Connect (6-12m) | AP28: Business Context & Org Awareness; | AQ28: slows improvement; | AR28: Run fortnightly utilization reviews with WFM + delivery owners to rebalance work; | CR28: Positive | CS28: Supervisor; | CT28: Queries were related to AI being implemented in day-to-day projects practically to which leader had addressed that specific agents are identified at DEA level to work with and implement changes. | CU28: High | CV28: Closed
A29: 28 | B29: 46167.386 | C29: 46167.404 | D29: JD386706@techmahindra.com | E29: Jeremiah Dave | F29: Jeremiah Dave | G29: 386706 | H29: 46152 | I29: Induction | J29: IBU Specific Connect | K29: PUNE | L29: DEA-D-2007 | M29: E | N29: Virtual | O29: NGS Service Line | P29: NWS-D-4001 | Q29: Bench connect for the IBUs | U29: Alignment | W29: New Joiner Connect (60 Days) | BN29: Team Integration;Queries related to BGV check; | BO29: NA; | BP29: NA;The associates had queries mainly related to WFH and leaves.; | CR29: Negative | CS29: No specific Action, Issue addressed in meeting; | CT29: NA | CU29: Moderate | CV29: Closed
A30: 29 | B30: 46154.216 | C30: 46154.222 | D30: AW831380@techmahindra.com | E30: Alka Wable | F30: Alka Wable | G30: 831380 | H30: 46142 | I30: Large Connect | J30: Practice Specific Connect (Across IBU) | K30: Rajpur Sonarpur | L30: TMC-D-1001 | M30: MIX | N30: In-person-Tech M | O30: DEA Service Line | P30: DIG-D-4001, DIG-D-4005, DIG-D-4007 | Q30: ZF Consultancy | U30: Empowerment | Y30: Women Associate Connect | BZ30: Career Support & Sponsorship;Empathy And Communication; | CA30: Upskilling for future roles;Female assocaites in Haleon office are quite happy with the setup; | CB30: Leadership acknowledgment;Reinforce speak-up channels; | CR30: Neutral | CS30: No specific Action, Issue addressed in meeting; | CT30: NA | CU30: High | CV30: Closed
A31: 30 | B31: 46203.344 | C31: 46203.354 | D31: DR781403@techmahindra.com | E31: Devika Rastogi | F31: Raksha Varughese | G31: 781403 | H31: 46193 | I31: Location-Offshore | J31: Location Specific Connect | K31: Kolkata | L31: TMC-D-1001 | M31: U | N31: Virtual | O31: DEA Service Line | P31: DIG-D-1001 | Q31: ServiceNow Practice | U31: Empowerment | Y31: Women Associate Connect | BZ31: Career Support & Sponsorship;Inclusive Team Practices;Work-Life Balance & Flexibility; | CA31: Need empathy and communication; | CB31: Reinforce speak-up channels; | CR31: Neutral | CS31: No specific Action, Issue addressed in meeting; | CT31: None | CU31: Moderate | CV31: Closed
A32: 31 | B32: 46116.204 | C32: 46116.209 | D32: UB278240@techmahindra.com | E32: Umang Bhatt | F32: Umang Bhatt | G32: 278240 | H32: 46097 | I32: Location-Offshore | J32: IBU Specific Connect | K32: Jaipur | L32: DEA-D-2005 | M32: MIX | N32: Virtual | O32: DEA Service Line | P32: DIG-D-4001, DIG-D-4005, DIG-D-4007 | Q32: Adani | U32: Empowerment | Y32: Band Specific FGD Connect | CC32: Review of ongoing concerns;Feedback on recent processes; | CD32: Minor process related queries; | CE32: No specific action required;Monitor and follow up in next cycle; | CR32: Neutral | CS32: No specific Action, Issue addressed in meeting; | CT32: NA | CU32: Moderate | CV32: Closed
A33: 32 | B33: 46141.176 | C33: 46141.191 | D33: TA410244@techmahindra.com | E33: Thomas Amble | F33: Thomas Amble | G33: 410244 | H33: 46132 | I33: Large Connect | J33: Practice Specific Connect (Across IBU) | K33: Bengaluru | L33: DEA- D-4023, DEA-D-4024, DEA-D-4025 | M33: E | N33: In-person-Tech M | O33: CIS Service Line | P33: SAP Retail | Q33: IFS SELL TO | S33: Distributed TMC specific Swag Kit | U33: Recognition | X33: Exclusive Award Ceremony | CR33: Positive | CS33: No specific Action, Issue addressed in meeting; | CT33: NA | CU33: Low | CV33: Closed
A34: 33 | B34: 46046.756 | C34: 46046.758 | D34: VB423939@techmahindra.com | E34: Veer Bir | F34: Veer Bir | G34: 423939 | H34: 46045 | I34: 1:1 | J34: Practice Specific Connect (Across IBU) | K34: Bathinda | L34: DEA-D-4021 | M34: MIX | N34: Virtual | O34: DEA Service Line | P34: MFG-N-4007 | Q34: SAP | U34: Empowerment | Y34: Skip Meeting | BW34: Timely Policy/process Updates;Manager Effectiveness & Delegation;Communication & Transparency; | BX34: Need timely policy/process updates;Need clarity on growth opportunities; | BY34: Set comms cadence;Standardize messaging; | CR34: Mixed | CS34: No specific Action, Issue addressed in meeting; | CT34: tracker | CU34: Low | CV34: Open | CW34: SALESFORCE PRACTICE
A35: 34 | B35: 46046.731 | C35: 46046.733 | D35: AS377304@techmahindra.com | E35: Arya Sunder | F35: Arya Sunder | G35: 377304 | H35: 46032 | I35: FGD | J35: Practice Specific Connect (Across IBU) | K35: Panvel | L35: IIGA | M35: U | N35: Mix (Virtual & In-person) | O35: DEA Service Line | P35: DEA-D-2004 | Q35: Oracle HCM – UKG & Workday | U35: Career | V35: ELTP Connect (<6m) | AM35: Review of ongoing concerns;Feedback on recent processes; | AN35: Minor process related queries; | AO35: Share update with relevant stakeholder;NA; | CR35: Positive | CS35: HRBP;Delivery; | CU35: Moderate | CV35: In-progress
A36: 35 | B36: 46057.948 | C36: 46057.967 | D36: XS830316@techmahindra.com | E36: Xavier Solanki | F36: Xavier Solanki | G36: 830316 | H36: 46044 | I36: 1:1 | J36: Practice Specific Connect (Across IBU) | K36: Bhubaneswar | L36: TMC-D-1001 | M36: MIX | N36: Mix (Virtual & In-person) | O36: DEA Service Line | P36: DIG-D-4005 | Q36: Mixed | U36: Alignment | W36: New Joiner Connect (90 Days) | BQ36: Internal Growth Opportunities; | BR36: seat allocation; | BS36: Share internal job/cross-skill opportunities;Align role expectations vs aspiration through discussion; | CR36: Positive | CS36: No specific Action, Issue addressed in meeting; | CT36: NA | CU36: Low | CV36: Closed
A37: 36 | B37: 46181.183 | C37: 46181.203 | D37: GC449709@techmahindra.com | E37: Girindra Chatterjee | F37: Girindra Chatterjee | G37: 449709 | H37: 46177 | I37: Floor Connect | J37: IBU Specific Connect | K37: Hyderabad | L37: DEA-D-2007 | M37: U | N37: Virtual | O37: DIG Vertical | P37: MFG-N-4007 | Q37: SAP Sell To | U37: Career | V37: ELTP Connect (12-24m) | AS37: Career Progression & Next-Level Readiness; | AT37: ELTPs want clarity on progression timelines and competencies for the next band/role;na; | AU37: Highlight ELTP success stories + learning milestones in leadership forums/townhalls; | CR37: Positive | CS37: HRBP; | CU37: Moderate | CV37: Closed
A38: 37 | B38: 46154.076 | C38: 46154.088 | D38: PR570050@techmahindra.com | E38: Pallavi Roy | F38: Pallavi Roy | G38: 570050 | H38: 46138 | I38: 1:1 | J38: IBU Specific Connect | K38: Meerut | L38: DEA- D-4023, DEA-D-4024, DEA-D-4025 | M38: MIX | N38: In-person-Tech M | O38: DEA Service Line | P38: DEA-D-4008 | Q38: OPTUS | U38: Alignment | W38: Townhall | AA38: Leadership Communication & Q&A Effectiveness; | AB38: Org/structural updates are heard but not fully understood (what changes for me?);Need clearer articulation of business direction and priorities for the quarter; | AC38: NA; | CR38: Neutral | CS38: No specific Action, Issue addressed in meeting; | CT38: Open house connect for offshore | CU38: Low | CV38: Closed
A39: 38 | B39: 46156.701 | C39: 46156.71 | D39: DR499407@techmahindra.com | E39: Darsh Rau | F39: Darsh Rau | G39: 499407 | H39: 46140 | I39: FGD | J39: IBU Specific Connect | K39: Bhubaneswar | L39: DEA-D-2007 | M39: MIX | N39: In-person-Tech M | O39: DEA Service Line | P39: NGS-D-4018 | Q39: OPTUS | U39: Alignment | W39: SL Induction | AD39: HR / WFM / Training Communication Effectiveness;Engagement with Leadership & Confidence Level; | AE39: Associates unclear how their role contributes to business;Associates lack clarity on practice goals and IBU priorities; | AF39: Checked the action plan for pending allocation of new joiners and highlighted to IBU head and it was closed;TLS SPOC had cleared all the queries w.r.t learning; | CR39: Neutral | CS39: No specific Action, Issue addressed in meeting; | CT39: NA | CU39: High | CV39: Closed
A40: 39 | B40: 46166.712 | C40: 46166.716 | D40: YH530764@techmahindra.com | E40: Yuvraj Handa | F40: Yuvraj Handa | G40: 530764 | H40: 46153 | I40: Location-Offshore | J40: Practice Specific Connect (Across IBU) | K40: Hyderbad | L40: DIG-D-4002, 4003, 4007,4009 | M40: MIX | N40: Virtual | O40: DEA Service Line | P40: DEA-D-4023 | Q40: GE | U40: Empowerment | Y40: Skip Meeting | BW40: Manager Effectiveness & Delegation;Communication & Transparency;Learning/cert Support Requests; | BX40: Need timely policy/process updates; | BY40: Team recognition cadence; | CR40: Mixed | CS40: WFM; | CU40: Low | CV40: Closed
...

Sheet Calc
A1: KPI FORMULAS | G1: ENGAGEMENT TYPE | J1: SL x SEVERITY | Q1: COVERAGE ISSUES (self-populating from Data_Summary) | W1: COVERAGE BREAKDOWN | AA1: SESSION DISTRIBUTION BY COHORT | AD1: TOP ORGANIZATIONAL CONCERNS (chart feed) | AG1: ENGAGEMENT TYPE (sorted feed) | AJ1: COVERAGE STATEMENT FREQ
A2: KPI | B2: Value | G2: Type | H2: Count | J2: Service Line | K2: High | L2: Moderate | M2: Low | N2: Total | Q2: Coverage Issue | R2: BHR Count | S2: % of Sessions | T2: Top Engagement Type | W2: Engagement / Coverage Area | X2: Sessions Covered | AA2: Cohort | AB2: Sessions | AD2: Concern | AE2: Mentions | AG2: Engagement Type | AH2: Count | AJ2: Statement | AK2: Count
A3: Total Sessions | B3: =COUNTA(RawData[ID]) -> 300 | G3: Large Connect | H3: =COUNTIF(RawData[Engagement Type],G3) -> 96 | J3: DEA Service Line | K3: =COUNTIFS(RawData[Service Line],J3,RawData[Severity],"High") -> 43 | L3: =COUNTIFS(RawData[Service Line],J3,RawData[Severity],"Moderate") -> 79 | M3: =COUNTIFS(RawData[Service Line],J3,RawData[Severity],"Low") -> 78 | N3: =SUM(K3:M3) -> 200 | Q3: {=IFERROR(INDEX($AJ$2:$AJ$599,MATCH(1,($AK$2:$AK$599=R3)*(COUNTIF($Q2:$Q$3,$AJ$2:$AJ$599)=0)*($AJ$2:$AJ$599<>""),0)),"")} -> Feedback on recent processes | R3: =IFERROR(LARGE($AK$2:$AK$599,1),"") -> 24 | S3: =IF(Q3="","",IFERROR(R3/$B$3,0)) -> 0.08 | T3: {=IF(Q3="","",IFERROR(INDEX(SummaryData[Engagement Type],MATCH(TRIM(Q3),TRIM(SummaryData[Statement]),0)),""))} -> 1:1 | W3: HR Connect (General) | X3: =SUMPRODUCT((TRIM(RawData[Alignment])=TRIM(W3))*1) -> 14 | AA3: {=IFERROR(INDEX($AM$2:$AM$199,MATCH(1,($AN$2:$AN$199=AB3)*(COUNTIF($AA2:$AA$3,$AM$2:$AM$199)=0)*($AM$2:$AM$199<>""),0)),"")} -> HR Connect (Project Wise) | AB3: =IFERROR(LARGE($AN$2:$AN$199,1),"") -> 30 | AD3: =IF(Calc!Q3="","",Calc!Q3) -> Feedback on recent processes | AE3: =IF(Calc!Q3="","",Calc!R3) -> 24 | AG3: {=IFERROR(INDEX($G$3:$G$15,MATCH(1,(($H$3:$H$15)=AH3)*(COUNTIF($AG2:$AG$3,$G$3:$G$15)=0),0)),"")} -> Large Connect | AH3: =IFERROR(LARGE($H$3:$H$15,1),"") -> 96 | AJ3: =IF(Data_Summary!Y3<>"Coverage","",IF(Data_Summary!AA3="","",IF(COUNTIFS(Data_Summary!$Y$2:$Y3,"Coverage",Data_Summary!$AA$2:$AA3,Data_Summary!AA3)=1,Data_Summary!AA3,""))) | AK3: =IF(AJ3="","",COUNTIFS(Data_Summary!$Y$2:$Y$20001,"Coverage",Data_Summary!$AA$2:$AA$20001,AJ3))
A4: Open Concerns | B4: =COUNTIF(RawData[Status],"Open") -> 29 | G4: FGD | H4: =COUNTIF(RawData[Engagement Type],G4) -> 59 | J4: MFG Vertical | K4: =COUNTIFS(RawData[Service Line],J4,RawData[Severity],"High") -> 1 | L4: =COUNTIFS(RawData[Service Line],J4,RawData[Severity],"Moderate") -> 5 | M4: =COUNTIFS(RawData[Service Line],J4,RawData[Severity],"Low") -> 0 | N4: =SUM(K4:M4) -> 6 | Q4: {=IFERROR(INDEX($AJ$2:$AJ$599,MATCH(1,($AK$2:$AK$599=R4)*(COUNTIF($Q$3:$Q3,$AJ$2:$AJ$599)=0)*($AJ$2:$AJ$599<>""),0)),"")} -> Clarity on expectations | R4: =IFERROR(LARGE($AK$2:$AK$599,2),"") -> 19 | S4: =IF(Q4="","",IFERROR(R4/$B$3,0)) -> 0.063333333 | T4: {=IF(Q4="","",IFERROR(INDEX(SummaryData[Engagement Type],MATCH(TRIM(Q4),TRIM(SummaryData[Statement]),0)),""))} -> Large Connect | W4: HR Connect (Project-Wise) | X4: =SUMPRODUCT((TRIM(RawData[Alignment])=TRIM(W4))*1) -> 0 | AA4: {=IFERROR(INDEX($AM$2:$AM$199,MATCH(1,($AN$2:$AN$199=AB4)*(COUNTIF($AA$3:$AA3,$AM$2:$AM$199)=0)*($AM$2:$AM$199<>""),0)),"")} -> New Joiner Connect (60 Days) | AB4: =IFERROR(LARGE($AN$2:$AN$199,2),"") -> 22 | AD4: =IF(Calc!Q4="","",Calc!Q4) -> Clarity on expectations | AE4: =IF(Calc!Q4="","",Calc!R4) -> 19 | AG4: {=IFERROR(INDEX($G$3:$G$15,MATCH(1,(($H$3:$H$15)=AH4)*(COUNTIF($AG$3:$AG3,$G$3:$G$15)=0),0)),"")} -> FGD | AH4: =IFERROR(LARGE($H$3:$H$15,2),"") -> 59 | AJ4: =IF(Data_Summary!Y5<>"Coverage","",IF(Data_Summary!AA5="","",IF(COUNTIFS(Data_Summary!$Y$2:$Y5,"Coverage",Data_Summary!$AA$2:$AA5,Data_Summary!AA5)=1,Data_Summary!AA5,""))) | AK4: =IF(AJ4="","",COUNTIFS(Data_Summary!$Y$2:$Y$20001,"Coverage",Data_Summary!$AA$2:$AA$20001,AJ4))
A5: In Progress | B5: =COUNTIF(RawData[Status],"In-progress") -> 57 | G5: 1:1 | H5: =COUNTIF(RawData[Engagement Type],G5) -> 59 | J5: Network Services Service Line | K5: =COUNTIFS(RawData[Service Line],J5,RawData[Severity],"High") -> 2 | L5: =COUNTIFS(RawData[Service Line],J5,RawData[Severity],"Moderate") -> 3 | M5: =COUNTIFS(RawData[Service Line],J5,RawData[Severity],"Low") -> 4 | N5: =SUM(K5:M5) -> 9 | Q5: {=IFERROR(INDEX($AJ$2:$AJ$599,MATCH(1,($AK$2:$AK$599=R5)*(COUNTIF($Q$3:$Q4,$AJ$2:$AJ$599)=0)*($AJ$2:$AJ$599<>""),0)),"")} -> General wellbeing check-in | R5: =IFERROR(LARGE($AK$2:$AK$599,3),"") -> 16 | S5: =IF(Q5="","",IFERROR(R5/$B$3,0)) -> 0.053333333 | T5: {=IF(Q5="","",IFERROR(INDEX(SummaryData[Engagement Type],MATCH(TRIM(Q5),TRIM(SummaryData[Statement]),0)),""))} -> Location-Offshore | W5: New Joinee Connect (7 Days) | X5: =SUMPRODUCT((TRIM(RawData[Alignment])=TRIM(W5))*1) -> 0 | AA5: {=IFERROR(INDEX($AM$2:$AM$199,MATCH(1,($AN$2:$AN$199=AB5)*(COUNTIF($AA$3:$AA4,$AM$2:$AM$199)=0)*($AM$2:$AM$199<>""),0)),"")} -> New Joiner Connect (30 Days) | AB5: =IFERROR(LARGE($AN$2:$AN$199,3),"") -> 19 | AD5: =IF(Calc!Q5="","",Calc!Q5) -> General wellbeing check-in | AE5: =IF(Calc!Q5="","",Calc!R5) -> 16 | AG5: {=IFERROR(INDEX($G$3:$G$15,MATCH(1,(($H$3:$H$15)=AH5)*(COUNTIF($AG$3:$AG4,$G$3:$G$15)=0),0)),"")} -> 1:1 | AH5: =IFERROR(LARGE($H$3:$H$15,3),"") -> 59 | AJ5: =IF(Data_Summary!Y6<>"Coverage","",IF(Data_Summary!AA6="","",IF(COUNTIFS(Data_Summary!$Y$2:$Y6,"Coverage",Data_Summary!$AA$2:$AA6,Data_Summary!AA6)=1,Data_Summary!AA6,""))) | AK5: =IF(AJ5="","",COUNTIFS(Data_Summary!$Y$2:$Y$20001,"Coverage",Data_Summary!$AA$2:$AA$20001,AJ5))
A6: Closed Actions | B6: =COUNTIF(RawData[Status],"Closed") -> 214 | G6: Floor Connect | H6: =COUNTIF(RawData[Engagement Type],G6) -> 36 | Q6: {=IFERROR(INDEX($AJ$2:$AJ$599,MATCH(1,($AK$2:$AK$599=R6)*(COUNTIF($Q$3:$Q5,$AJ$2:$AJ$599)=0)*($AJ$2:$AJ$599<>""),0)),"")} -> Team Integration | R6: =IFERROR(LARGE($AK$2:$AK$599,4),"") -> 13 | S6: =IF(Q6="","",IFERROR(R6/$B$3,0)) -> 0.043333333 | T6: {=IF(Q6="","",IFERROR(INDEX(SummaryData[Engagement Type],MATCH(TRIM(Q6),TRIM(SummaryData[Statement]),0)),""))} -> Induction | W6: New Joiner Connect (30 Days) | X6: =SUMPRODUCT((TRIM(RawData[Alignment])=TRIM(W6))*1) -> 19 | AA6: {=IFERROR(INDEX($AM$2:$AM$199,MATCH(1,($AN$2:$AN$199=AB6)*(COUNTIF($AA$3:$AA5,$AM$2:$AM$199)=0)*($AM$2:$AM$199<>""),0)),"")} -> New Joiner Connect (90 Days) | AB6: =IFERROR(LARGE($AN$2:$AN$199,4),"") -> 16 | AD6: =IF(Calc!Q6="","",Calc!Q6) -> Team Integration | AE6: =IF(Calc!Q6="","",Calc!R6) -> 13 | AG6: {=IFERROR(INDEX($G$3:$G$15,MATCH(1,(($H$3:$H$15)=AH6)*(COUNTIF($AG$3:$AG5,$G$3:$G$15)=0),0)),"")} -> Floor Connect | AH6: =IFERROR(LARGE($H$3:$H$15,4),"") -> 36 | AJ6: =IF(Data_Summary!Y7<>"Coverage","",IF(Data_Summary!AA7="","",IF(COUNTIFS(Data_Summary!$Y$2:$Y7,"Coverage",Data_Summary!$AA$2:$AA7,Data_Summary!AA7)=1,Data_Summary!AA7,""))) -> Business & Strategy Clarity | AK6: =IF(AJ6="","",COUNTIFS(Data_Summary!$Y$2:$Y$20001,"Coverage",Data_Summary!$AA$2:$AA$20001,AJ6)) -> 11
A7: High Severity | B7: =COUNTIF(RawData[Severity],"High") -> 63 | G7: Location-Offshore | H7: =COUNTIF(RawData[Engagement Type],G7) -> 19 | Q7: {=IFERROR(INDEX($AJ$2:$AJ$599,MATCH(1,($AK$2:$AK$599=R7)*(COUNTIF($Q$3:$Q6,$AJ$2:$AJ$599)=0)*($AJ$2:$AJ$599<>""),0)),"")} -> Workload & Work-Life Balance | R7: =IFERROR(LARGE($AK$2:$AK$599,5),"") -> 12 | S7: =IF(Q7="","",IFERROR(R7/$B$3,0)) -> 0.04 | T7: {=IF(Q7="","",IFERROR(INDEX(SummaryData[Engagement Type],MATCH(TRIM(Q7),TRIM(SummaryData[Statement]),0)),""))} -> FGD | W7: New Joiner Connect (60 Days) | X7: =SUMPRODUCT((TRIM(RawData[Alignment])=TRIM(W7))*1) -> 22 | AA7: {=IFERROR(INDEX($AM$2:$AM$199,MATCH(1,($AN$2:$AN$199=AB7)*(COUNTIF($AA$3:$AA6,$AM$2:$AM$199)=0)*($AM$2:$AM$199<>""),0)),"")} -> New Joiner Connect (7 Days) | AB7: =IFERROR(LARGE($AN$2:$AN$199,5),"") -> 16 | AD7: =IF(Calc!Q7="","",Calc!Q7) -> Workload & Work-Life Balance | AE7: =IF(Calc!Q7="","",Calc!R7) -> 12 | AG7: {=IFERROR(INDEX($G$3:$G$15,MATCH(1,(($H$3:$H$15)=AH7)*(COUNTIF($AG$3:$AG6,$G$3:$G$15)=0),0)),"")} -> Location-Offshore | AH7: =IFERROR(LARGE($H$3:$H$15,5),"") -> 19 | AJ7: =IF(Data_Summary!Y8<>"Coverage","",IF(Data_Summary!AA8="","",IF(COUNTIFS(Data_Summary!$Y$2:$Y8,"Coverage",Data_Summary!$AA$2:$AA8,Data_Summary!AA8)=1,Data_Summary!AA8,""))) -> Career Visibility & Skill Roadmap | AK7: =IF(AJ7="","",COUNTIFS(Data_Summary!$Y$2:$Y$20001,"Coverage",Data_Summary!$AA$2:$AA$20001,AJ7)) -> 7
A8: Moderate Severity | B8: =COUNTIF(RawData[Severity],"Moderate") -> 126 | G8: Workshop/Session | H8: =COUNTIF(RawData[Engagement Type],G8) -> 4 | Q8: {=IFERROR(INDEX($AJ$2:$AJ$599,MATCH(1,($AK$2:$AK$599=R8)*(COUNTIF($Q$3:$Q7,$AJ$2:$AJ$599)=0)*($AJ$2:$AJ$599<>""),0)),"")} -> Discussion on team dynamics | R8: =IFERROR(LARGE($AK$2:$AK$599,6),"") -> 12 | S8: =IF(Q8="","",IFERROR(R8/$B$3,0)) -> 0.04 | T8: {=IF(Q8="","",IFERROR(INDEX(SummaryData[Engagement Type],MATCH(TRIM(Q8),TRIM(SummaryData[Statement]),0)),""))} -> 1:1 | W8: New Joiner Connect (90 Days) | X8: =SUMPRODUCT((TRIM(RawData[Alignment])=TRIM(W8))*1) -> 16 | AA8: {=IFERROR(INDEX($AM$2:$AM$199,MATCH(1,($AN$2:$AN$199=AB8)*(COUNTIF($AA$3:$AA7,$AM$2:$AM$199)=0)*($AM$2:$AM$199<>""),0)),"")} -> Cadence Connect | AB8: =IFERROR(LARGE($AN$2:$AN$199,6),"") -> 12 | AD8: =IF(Calc!Q8="","",Calc!Q8) -> Discussion on team dynamics | AE8: =IF(Calc!Q8="","",Calc!R8) -> 12 | AG8: {=IFERROR(INDEX($G$3:$G$15,MATCH(1,(($H$3:$H$15)=AH8)*(COUNTIF($AG$3:$AG7,$G$3:$G$15)=0),0)),"")} -> Location-Mixed | AH8: =IFERROR(LARGE($H$3:$H$15,6),"") -> 8 | AJ8: =IF(Data_Summary!Y9<>"Coverage","",IF(Data_Summary!AA9="","",IF(COUNTIFS(Data_Summary!$Y$2:$Y9,"Coverage",Data_Summary!$AA$2:$AA9,Data_Summary!AA9)=1,Data_Summary!AA9,""))) -> AI/future Readiness Messaging Is High-level | AK8: =IF(AJ8="","",COUNTIFS(Data_Summary!$Y$2:$Y$20001,"Coverage",Data_Summary!$AA$2:$AA$20001,AJ8)) -> 4
A9: Low Severity | B9: =COUNTIF(RawData[Severity],"Low") -> 111 | G9: Connect with Women Associates | H9: =COUNTIF(RawData[Engagement Type],G9) -> 0 | Q9: {=IFERROR(INDEX($AJ$2:$AJ$599,MATCH(1,($AK$2:$AK$599=R9)*(COUNTIF($Q$3:$Q8,$AJ$2:$AJ$599)=0)*($AJ$2:$AJ$599<>""),0)),"")} -> Business & Strategy Clarity | R9: =IFERROR(LARGE($AK$2:$AK$599,7),"") -> 11 | S9: =IF(Q9="","",IFERROR(R9/$B$3,0)) -> 0.036666667 | T9: {=IF(Q9="","",IFERROR(INDEX(SummaryData[Engagement Type],MATCH(TRIM(Q9),TRIM(SummaryData[Statement]),0)),""))} -> Large Connect | W9: SL Induction | X9: =SUMPRODUCT((TRIM(RawData[Alignment])=TRIM(W9))*1) -> 21 | AA9: {=IFERROR(INDEX($AM$2:$AM$199,MATCH(1,($AN$2:$AN$199=AB9)*(COUNTIF($AA$3:$AA8,$AM$2:$AM$199)=0)*($AM$2:$AM$199<>""),0)),"")} -> Skip Meeting | AB9: =IFERROR(LARGE($AN$2:$AN$199,7),"") -> 11 | AD9: =IF(Calc!Q9="","",Calc!Q9) -> Business & Strategy Clarity | AE9: =IF(Calc!Q9="","",Calc!R9) -> 11 | AG9: {=IFERROR(INDEX($G$3:$G$15,MATCH(1,(($H$3:$H$15)=AH9)*(COUNTIF($AG$3:$AG8,$G$3:$G$15)=0),0)),"")} -> Induction | AH9: =IFERROR(LARGE($H$3:$H$15,7),"") -> 5 | AJ9: =IF(Data_Summary!Y10<>"Coverage","",IF(Data_Summary!AA10="","",IF(COUNTIFS(Data_Summary!$Y$2:$Y10,"Coverage",Data_Summary!$AA$2:$AA10,Data_Summary!AA10)=1,Data_Summary!AA10,""))) | AK9: =IF(AJ9="","",COUNTIFS(Data_Summary!$Y$2:$Y$20001,"Coverage",Data_Summary!$AA$2:$AA$20001,AJ9))
A10: Positive Sentiment | B10: =COUNTIF(RawData[Overall Sentiment],"Positive") -> 193 | G10: Location-Mixed | H10: =COUNTIF(RawData[Engagement Type],G10) -> 8 | Q10: {=IFERROR(INDEX($AJ$2:$AJ$599,MATCH(1,($AK$2:$AK$599=R10)*(COUNTIF($Q$3:$Q9,$AJ$2:$AJ$599)=0)*($AJ$2:$AJ$599<>""),0)),"")} -> HR / WFM / Training Communication Effectiveness | R10: =IFERROR(LARGE($AK$2:$AK$599,8),"") -> 11 | S10: =IF(Q10="","",IFERROR(R10/$B$3,0)) -> 0.036666667 | T10: {=IF(Q10="","",IFERROR(INDEX(SummaryData[Engagement Type],MATCH(TRIM(Q10),TRIM(SummaryData[Statement]),0)),""))} -> 1:1 | W10: Townhall | X10: {=SUMPRODUCT((TRIM(RawData[Alignment])=TRIM(W10))*1)} -> 18 | AA10: {=IFERROR(INDEX($AM$2:$AM$199,MATCH(1,($AN$2:$AN$199=AB10)*(COUNTIF($AA$3:$AA9,$AM$2:$AM$199)=0)*($AM$2:$AM$199<>""),0)),"")} -> Josh (Fun Engagements) | AB10: =IFERROR(LARGE($AN$2:$AN$199,8),"") -> 9 | AD10: =IF(Calc!Q10="","",Calc!Q10) -> HR / WFM / Training Communication Effectiveness | AE10: =IF(Calc!Q10="","",Calc!R10) -> 11 | AG10: {=IFERROR(INDEX($G$3:$G$15,MATCH(1,(($H$3:$H$15)=AH10)*(COUNTIF($AG$3:$AG9,$G$3:$G$15)=0),0)),"")} -> Workshop/Session | AH10: =IFERROR(LARGE($H$3:$H$15,8),"") -> 4 | AJ10: =IF(Data_Summary!Y11<>"Coverage","",IF(Data_Summary!AA11="","",IF(COUNTIFS(Data_Summary!$Y$2:$Y11,"Coverage",Data_Summary!$AA$2:$AA11,Data_Summary!AA11)=1,Data_Summary!AA11,""))) | AK10: =IF(AJ10="","",COUNTIFS(Data_Summary!$Y$2:$Y$20001,"Coverage",Data_Summary!$AA$2:$AA$20001,AJ10))
A11: Mixed Sentiment | B11: =COUNTIF(RawData[Overall Sentiment],"Mixed") -> 26 | G11: Account Based | H11: =COUNTIF(RawData[Engagement Type],G11) -> 0 | Q11: {=IFERROR(INDEX($AJ$2:$AJ$599,MATCH(1,($AK$2:$AK$599=R11)*(COUNTIF($Q$3:$Q10,$AJ$2:$AJ$599)=0)*($AJ$2:$AJ$599<>""),0)),"")} -> Manager Support & Local Leadership Effectiveness | R11: =IFERROR(LARGE($AK$2:$AK$599,9),"") -> 10 | S11: =IF(Q11="","",IFERROR(R11/$B$3,0)) -> 0.033333333 | T11: {=IF(Q11="","",IFERROR(INDEX(SummaryData[Engagement Type],MATCH(TRIM(Q11),TRIM(SummaryData[Statement]),0)),""))} -> FGD | W11: Skip Meeting | X11: {=SUMPRODUCT((TRIM(RawData[Empowerment])=TRIM(W11))*1)} -> 11 | AA11: {=IFERROR(INDEX($AM$2:$AM$199,MATCH(1,($AN$2:$AN$199=AB11)*(COUNTIF($AA$3:$AA10,$AM$2:$AM$199)=0)*($AM$2:$AM$199<>""),0)),"")} -> ELTP Connect (12-24m) | AB11: =IFERROR(LARGE($AN$2:$AN$199,9),"") -> 8 | AD11: =IF(Calc!Q11="","",Calc!Q11) -> Manager Support & Local Leadership Effectiveness | AE11: =IF(Calc!Q11="","",Calc!R11) -> 10 | AG11: {=IFERROR(INDEX($G$3:$G$15,MATCH(1,(($H$3:$H$15)=AH11)*(COUNTIF($AG$3:$AG10,$G$3:$G$15)=0),0)),"")} -> New Joiner Induction | AH11: =IFERROR(LARGE($H$3:$H$15,9),"") -> 4 | AJ11: =IF(Data_Summary!Y12<>"Coverage","",IF(Data_Summary!AA12="","",IF(COUNTIFS(Data_Summary!$Y$2:$Y12,"Coverage",Data_Summary!$AA$2:$AA12,Data_Summary!AA12)=1,Data_Summary!AA12,""))) | AK11: =IF(AJ11="","",COUNTIFS(Data_Summary!$Y$2:$Y$20001,"Coverage",Data_Summary!$AA$2:$AA$20001,AJ11))
A12: Neutral Sentiment | B12: =COUNTIF(RawData[Overall Sentiment],"Neutral") -> 77 | G12: Induction | H12: =COUNTIF(RawData[Engagement Type],G12) -> 5 | Q12: {=IFERROR(INDEX($AJ$2:$AJ$599,MATCH(1,($AK$2:$AK$599=R12)*(COUNTIF($Q$3:$Q11,$AJ$2:$AJ$599)=0)*($AJ$2:$AJ$599<>""),0)),"")} -> Queries related to BGV check | R12: =IFERROR(LARGE($AK$2:$AK$599,10),"") -> 10 | S12: =IF(Q12="","",IFERROR(R12/$B$3,0)) -> 0.033333333 | T12: {=IF(Q12="","",IFERROR(INDEX(SummaryData[Engagement Type],MATCH(TRIM(Q12),TRIM(SummaryData[Statement]),0)),""))} -> Induction | W12: Business Wait Connect | X12: {=SUMPRODUCT((TRIM(RawData[Career])=TRIM(W12))*1)} -> 1 | AA12: {=IFERROR(INDEX($AM$2:$AM$199,MATCH(1,($AN$2:$AN$199=AB12)*(COUNTIF($AA$3:$AA11,$AM$2:$AM$199)=0)*($AM$2:$AM$199<>""),0)),"")} -> Top Talent FGD Connect | AB12: =IFERROR(LARGE($AN$2:$AN$199,10),"") -> 7 | AD12: =IF(Calc!Q12="","",Calc!Q12) -> Queries related to BGV check | AE12: =IF(Calc!Q12="","",Calc!R12) -> 10 | AG12: {=IFERROR(INDEX($G$3:$G$15,MATCH(1,(($H$3:$H$15)=AH12)*(COUNTIF($AG$3:$AG11,$G$3:$G$15)=0),0)),"")} -> Leadership Connect | AH12: =IFERROR(LARGE($H$3:$H$15,10),"") -> 4 | AJ12: =IF(Data_Summary!Y13<>"Coverage","",IF(Data_Summary!AA13="","",IF(COUNTIFS(Data_Summary!$Y$2:$Y13,"Coverage",Data_Summary!$AA$2:$AA13,Data_Summary!AA13)=1,Data_Summary!AA13,""))) -> Visibility on Allocation & Demand | AK12: =IF(AJ12="","",COUNTIFS(Data_Summary!$Y$2:$Y$20001,"Coverage",Data_Summary!$AA$2:$AA$20001,AJ12)) -> 7 | AM12: =IF(Data_Insight!X12="","",IF(COUNTIF(Data_Insight!$X$2:$X12,Data_Insight!X12)=1,Data_Insight!X12,"")) -> Top Talent FGD Connect | AN12: =IF(AM12="","",COUNTIF(Data_Insight!$X$2:$X$20001,AM12)) -> 7
A13: Action Closure % | B13: =IFERROR(COUNTIF(RawData[Status],"Closed")/COUNTA(RawData[ID])*100,0) -> 71.333333 | G13: New Joiner Induction | H13: =COUNTIF(RawData[Engagement Type],G13) -> 4 | Q13: {=IFERROR(INDEX($AJ$2:$AJ$599,MATCH(1,($AK$2:$AK$599=R13)*(COUNTIF($Q$3:$Q12,$AJ$2:$AJ$599)=0)*($AJ$2:$AJ$599<>""),0)),"")} -> Engagement with Leadership & Confidence Level | R13: =IFERROR(LARGE($AK$2:$AK$599,11),"") -> 10 | S13: =IF(Q13="","",IFERROR(R13/$B$3,0)) -> 0.033333333 | T13: {=IF(Q13="","",IFERROR(INDEX(SummaryData[Engagement Type],MATCH(TRIM(Q13),TRIM(SummaryData[Statement]),0)),""))} -> FGD | W13: Top Talent Connect (One to One) (Exclusives/Ascend/WLP/Mentor) | X13: {=SUMPRODUCT((TRIM(RawData[Career])=TRIM(W13))*1)} -> 0 | AA13: {=IFERROR(INDEX($AM$2:$AM$199,MATCH(1,($AN$2:$AN$199=AB13)*(COUNTIF($AA$3:$AA12,$AM$2:$AM$199)=0)*($AM$2:$AM$199<>""),0)),"")} -> Leadership Connect | AB13: =IFERROR(LARGE($AN$2:$AN$199,11),"") -> 7 | AG13: {=IFERROR(INDEX($G$3:$G$15,MATCH(1,(($H$3:$H$15)=AH13)*(COUNTIF($AG$3:$AG12,$G$3:$G$15)=0),0)),"")} -> Monthly Cadence | AH13: =IFERROR(LARGE($H$3:$H$15,11),"") -> 3 | AJ13: =IF(Data_Summary!Y14<>"Coverage","",IF(Data_Summary!AA14="","",IF(COUNTIFS(Data_Summary!$Y$2:$Y14,"Coverage",Data_Summary!$AA$2:$AA14,Data_Summary!AA14)=1,Data_Summary!AA14,""))) | AK13: =IF(AJ13="","",COUNTIFS(Data_Summary!$Y$2:$Y$20001,"Coverage",Data_Summary!$AA$2:$AA$20001,AJ13)) | AM13: =IF(Data_Insight!X13="","",IF(COUNTIF(Data_Insight!$X$2:$X13,Data_Insight!X13)=1,Data_Insight!X13,"")) -> Leadership Connect | AN13: =IF(AM13="","",COUNTIF(Data_Insight!$X$2:$X$20001,AM13)) -> 7
A14: Sentiment Score | B14: =IFERROR((COUNTIF(RawData[Overall Sentiment],"Positive")*100+COUNTIF(RawData[Overall Sentiment],"Neutral")*50+COUNTIF(RawData[Overall Sentiment],"Mixed")*25)/COUNTA(RawData[ID]),0) -> 79.333333 | G14: Leadership Connect | H14: =COUNTIF(RawData[Engagement Type],G14) -> 4 | Q14: {=IFERROR(INDEX($AJ$2:$AJ$599,MATCH(1,($AK$2:$AK$599=R14)*(COUNTIF($Q$3:$Q13,$AJ$2:$AJ$599)=0)*($AJ$2:$AJ$599<>""),0)),"")} -> Role Confidence Level | R14: =IFERROR(LARGE($AK$2:$AK$599,12),"") -> 9 | S14: =IF(Q14="","",IFERROR(R14/$B$3,0)) -> 0.03 | T14: {=IF(Q14="","",IFERROR(INDEX(SummaryData[Engagement Type],MATCH(TRIM(Q14),TRIM(SummaryData[Statement]),0)),""))} -> Large Connect | W14: Top Talent FGD Connect (Exclusives/Ascend/WLP/Mentor) | X14: {=SUMPRODUCT((TRIM(RawData[Career])=TRIM(W14))*1)} -> 0 | AA14: {=IFERROR(INDEX($AM$2:$AM$199,MATCH(1,($AN$2:$AN$199=AB14)*(COUNTIF($AA$3:$AA13,$AM$2:$AM$199)=0)*($AM$2:$AM$199<>""),0)),"")} -> Top Talent Connect | AB14: =IFERROR(LARGE($AN$2:$AN$199,12),"") -> 6 | AG14: {=IFERROR(INDEX($G$3:$G$15,MATCH(1,(($H$3:$H$15)=AH14)*(COUNTIF($AG$3:$AG13,$G$3:$G$15)=0),0)),"")} -> Connect with Women Associates | AH14: =IFERROR(LARGE($H$3:$H$15,12),"") -> 0 | AJ14: =IF(Data_Summary!Y15<>"Coverage","",IF(Data_Summary!AA15="","",IF(COUNTIFS(Data_Summary!$Y$2:$Y15,"Coverage",Data_Summary!$AA$2:$AA15,Data_Summary!AA15)=1,Data_Summary!AA15,""))) | AK14: =IF(AJ14="","",COUNTIFS(Data_Summary!$Y$2:$Y$20001,"Coverage",Data_Summary!$AA$2:$AA$20001,AJ14)) | AM14: =IF(Data_Insight!X14="","",IF(COUNTIF(Data_Insight!$X$2:$X14,Data_Insight!X14)=1,Data_Insight!X14,"")) -> New Joiner Connect (30 Days) | AN14: =IF(AM14="","",COUNTIF(Data_Insight!$X$2:$X$20001,AM14)) -> 19
A15: Total BHRs | B15: {=SUMPRODUCT((RawData[BHR Name]<>"")/COUNTIF(RawData[BHR Name],RawData[BHR Name]&""))} -> 299 | G15: Monthly Cadence | H15: =COUNTIF(RawData[Engagement Type],G15) -> 3 | Q15: {=IFERROR(INDEX($AJ$2:$AJ$599,MATCH(1,($AK$2:$AK$599=R15)*(COUNTIF($Q$3:$Q14,$AJ$2:$AJ$599)=0)*($AJ$2:$AJ$599<>""),0)),"")} -> Engagement & Belonging | R15: =IFERROR(LARGE($AK$2:$AK$599,13),"") -> 9 | S15: =IF(Q15="","",IFERROR(R15/$B$3,0)) -> 0.03 | T15: {=IF(Q15="","",IFERROR(INDEX(SummaryData[Engagement Type],MATCH(TRIM(Q15),TRIM(SummaryData[Statement]),0)),""))} -> FGD | W15: LSA Connect | X15: {=SUMPRODUCT((TRIM(RawData[Recognition])=TRIM(W15))*1)} -> 3 | AA15: {=IFERROR(INDEX($AM$2:$AM$199,MATCH(1,($AN$2:$AN$199=AB15)*(COUNTIF($AA$3:$AA14,$AM$2:$AM$199)=0)*($AM$2:$AM$199<>""),0)),"")} -> ELTP Connect (<6m) | AB15: =IFERROR(LARGE($AN$2:$AN$199,13),"") -> 6 | AG15: {=IFERROR(INDEX($G$3:$G$15,MATCH(1,(($H$3:$H$15)=AH15)*(COUNTIF($AG$3:$AG14,$G$3:$G$15)=0),0)),"")} -> Account Based | AH15: =IFERROR(LARGE($H$3:$H$15,13),"") -> 0 | AJ15: =IF(Data_Summary!Y16<>"Coverage","",IF(Data_Summary!AA16="","",IF(COUNTIFS(Data_Summary!$Y$2:$Y16,"Coverage",Data_Summary!$AA$2:$AA16,Data_Summary!AA16)=1,Data_Summary!AA16,""))) | AK15: =IF(AJ15="","",COUNTIFS(Data_Summary!$Y$2:$Y$20001,"Coverage",Data_Summary!$AA$2:$AA$20001,AJ15)) | AM15: =IF(Data_Insight!X15="","",IF(COUNTIF(Data_Insight!$X$2:$X15,Data_Insight!X15)=1,Data_Insight!X15,"")) | AN15: =IF(AM15="","",COUNTIF(Data_Insight!$X$2:$X$20001,AM15))
A16: Total SLs | B16: =IFERROR(SUMPRODUCT((RawData[Service Line]<>"")/COUNTIF(RawData[Service Line],RawData[Service Line]&"")),0) -> 10 | Q16: {=IFERROR(INDEX($AJ$2:$AJ$599,MATCH(1,($AK$2:$AK$599=R16)*(COUNTIF($Q$3:$Q15,$AJ$2:$AJ$599)=0)*($AJ$2:$AJ$599<>""),0)),"")} -> Business & Practice Awareness | R16: =IFERROR(LARGE($AK$2:$AK$599,14),"") -> 8 | S16: =IF(Q16="","",IFERROR(R16/$B$3,0)) -> 0.026666667 | T16: {=IF(Q16="","",IFERROR(INDEX(SummaryData[Engagement Type],MATCH(TRIM(Q16),TRIM(SummaryData[Statement]),0)),""))} -> Large Connect | W16: Exclusives Award Ceremony (Not part of Townhall) | X16: {=SUMPRODUCT((TRIM(RawData[Recognition])=TRIM(W16))*1)} -> 0 | AA16: {=IFERROR(INDEX($AM$2:$AM$199,MATCH(1,($AN$2:$AN$199=AB16)*(COUNTIF($AA$3:$AA15,$AM$2:$AM$199)=0)*($AM$2:$AM$199<>""),0)),"")} -> ELTP Connect (Practice Level) | AB16: =IFERROR(LARGE($AN$2:$AN$199,14),"") -> 5 | AJ16: =IF(Data_Summary!Y17<>"Coverage","",IF(Data_Summary!AA17="","",IF(COUNTIFS(Data_Summary!$Y$2:$Y17,"Coverage",Data_Summary!$AA$2:$AA17,Data_Summary!AA17)=1,Data_Summary!AA17,""))) | AK16: =IF(AJ16="","",COUNTIFS(Data_Summary!$Y$2:$Y$20001,"Coverage",Data_Summary!$AA$2:$AA$20001,AJ16)) | AM16: =IF(Data_Insight!X16="","",IF(COUNTIF(Data_Insight!$X$2:$X16,Data_Insight!X16)=1,Data_Insight!X16,"")) | AN16: =IF(AM16="","",COUNTIF(Data_Insight!$X$2:$X$20001,AM16))
A17: Most Active SL | B17: {=IFERROR(INDEX(RawData[Service Line],MATCH(MAX(COUNTIF(RawData[Service Line],RawData[Service Line])),COUNTIF(RawData[Service Line],RawData[Service Line]),0)),"N/A")} -> DEA Service Line | Q17: {=IFERROR(INDEX($AJ$2:$AJ$599,MATCH(1,($AK$2:$AK$599=R17)*(COUNTIF($Q$3:$Q16,$AJ$2:$AJ$599)=0)*($AJ$2:$AJ$599<>""),0)),"")} -> Project Allocation Clarity | R17: =IFERROR(LARGE($AK$2:$AK$599,15),"") -> 8 | S17: =IF(Q17="","",IFERROR(R17/$B$3,0)) -> 0.026666667 | T17: {=IF(Q17="","",IFERROR(INDEX(SummaryData[Engagement Type],MATCH(TRIM(Q17),TRIM(SummaryData[Statement]),0)),""))} -> 1:1 | W17: ELTP Connect - Practice Level | X17: {=SUMPRODUCT((TRIM(RawData[Empowerment])=TRIM(W17))*1)} -> 0 | AA17: {=IFERROR(INDEX($AM$2:$AM$199,MATCH(1,($AN$2:$AN$199=AB17)*(COUNTIF($AA$3:$AA16,$AM$2:$AM$199)=0)*($AM$2:$AM$199<>""),0)),"")} -> Exclusive Award Ceremony | AB17: =IFERROR(LARGE($AN$2:$AN$199,15),"") -> 5 | AJ17: =IF(Data_Summary!Y18<>"Coverage","",IF(Data_Summary!AA18="","",IF(COUNTIFS(Data_Summary!$Y$2:$Y18,"Coverage",Data_Summary!$AA$2:$AA18,Data_Summary!AA18)=1,Data_Summary!AA18,""))) -> General wellbeing check-in | AK17: =IF(AJ17="","",COUNTIFS(Data_Summary!$Y$2:$Y$20001,"Coverage",Data_Summary!$AA$2:$AA$20001,AJ17)) -> 16 | AM17: =IF(Data_Insight!X17="","",IF(COUNTIF(Data_Insight!$X$2:$X17,Data_Insight!X17)=1,Data_Insight!X17,"")) -> HR Connect (Project Wise) | AN17: =IF(AM17="","",COUNTIF(Data_Insight!$X$2:$X$20001,AM17)) -> 30
A18: IBU/Practice/Location | B18: {=IFERROR(INDEX(RawData[IBU/Practice/Location],MATCH(MAX(COUNTIF(RawData[IBU/Practice/Location],RawData[IBU/Practice/Location])),COUNTIF(RawData[IBU/Practice/Location],RawData[IBU/Practice/Location]),0)),"N/A")} -> IBU Specific Connect | Q18: {=IFERROR(INDEX($AJ$2:$AJ$599,MATCH(1,($AK$2:$AK$599=R18)*(COUNTIF($Q$3:$Q17,$AJ$2:$AJ$599)=0)*($AJ$2:$AJ$599<>""),0)),"")} -> Career Path Visibility | R18: =IFERROR(LARGE($AK$2:$AK$599,16),"") -> 8 | S18: =IF(Q18="","",IFERROR(R18/$B$3,0)) -> 0.026666667 | T18: {=IF(Q18="","",IFERROR(INDEX(SummaryData[Engagement Type],MATCH(TRIM(Q18),TRIM(SummaryData[Statement]),0)),""))} -> Large Connect | W18: ELTP Connect (<6m) | X18: {=SUMPRODUCT((TRIM(RawData[Empowerment])=TRIM(W18))*1)} -> 0 | AJ18: =IF(Data_Summary!Y19<>"Coverage","",IF(Data_Summary!AA19="","",IF(COUNTIFS(Data_Summary!$Y$2:$Y19,"Coverage",Data_Summary!$AA$2:$AA19,Data_Summary!AA19)=1,Data_Summary!AA19,""))) | AK18: =IF(AJ18="","",COUNTIFS(Data_Summary!$Y$2:$Y$20001,"Coverage",Data_Summary!$AA$2:$AA$20001,AJ18)) | AM18: =IF(Data_Insight!X18="","",IF(COUNTIF(Data_Insight!$X$2:$X18,Data_Insight!X18)=1,Data_Insight!X18,"")) -> ELTP Connect (12-24m) | AN18: =IF(AM18="","",COUNTIF(Data_Insight!$X$2:$X$20001,AM18)) -> 8
A19: Top CARES Lever | B19: {=IFERROR(INDEX(RawData[CARES Framework],MATCH(MAX(COUNTIF(RawData[CARES Framework],RawData[CARES Framework])),COUNTIF(RawData[CARES Framework],RawData[CARES Framework]),0)),"N/A")} -> Alignment | Q19: {=IFERROR(INDEX($AJ$2:$AJ$599,MATCH(1,($AK$2:$AK$599=R19)*(COUNTIF($Q$3:$Q18,$AJ$2:$AJ$599)=0)*($AJ$2:$AJ$599<>""),0)),"")} -> Policy & Process Clarity | R19: =IFERROR(LARGE($AK$2:$AK$599,17),"") -> 8 | S19: =IF(Q19="","",IFERROR(R19/$B$3,0)) -> 0.026666667 | T19: {=IF(Q19="","",IFERROR(INDEX(SummaryData[Engagement Type],MATCH(TRIM(Q19),TRIM(SummaryData[Statement]),0)),""))} -> Large Connect | W19: ELTP Connect (6- 12m) | X19: {=SUMPRODUCT((TRIM(RawData[Empowerment])=TRIM(W19))*1)} -> 0 | AJ19: =IF(Data_Summary!Y20<>"Coverage","",IF(Data_Summary!AA20="","",IF(COUNTIFS(Data_Summary!$Y$2:$Y20,"Coverage",Data_Summary!$AA$2:$AA20,Data_Summary!AA20)=1,Data_Summary!AA20,""))) | AK19: =IF(AJ19="","",COUNTIFS(Data_Summary!$Y$2:$Y$20001,"Coverage",Data_Summary!$AA$2:$AA$20001,AJ19)) | AM19: =IF(Data_Insight!X19="","",IF(COUNTIF(Data_Insight!$X$2:$X19,Data_Insight!X19)=1,Data_Insight!X19,"")) | AN19: =IF(AM19="","",COUNTIF(Data_Insight!$X$2:$X$20001,AM19))
A20: Open+InProgress | B20: =COUNTIF(RawData[Status],"Open")+COUNTIF(RawData[Status],"In-progress") -> 86 | Q20: {=IFERROR(INDEX($AJ$2:$AJ$599,MATCH(1,($AK$2:$AK$599=R20)*(COUNTIF($Q$3:$Q19,$AJ$2:$AJ$599)=0)*($AJ$2:$AJ$599<>""),0)),"")} -> Induction Effectiveness | R20: =IFERROR(LARGE($AK$2:$AK$599,18),"") -> 8 | S20: =IF(Q20="","",IFERROR(R20/$B$3,0)) -> 0.026666667 | T20: {=IF(Q20="","",IFERROR(INDEX(SummaryData[Engagement Type],MATCH(TRIM(Q20),TRIM(SummaryData[Statement]),0)),""))} -> FGD | W20: ELTP Connect (12-24m) | X20: {=SUMPRODUCT((TRIM(RawData[Empowerment])=TRIM(W20))*1)} -> 0 | AJ20: =IF(Data_Summary!Y21<>"Coverage","",IF(Data_Summary!AA21="","",IF(COUNTIFS(Data_Summary!$Y$2:$Y21,"Coverage",Data_Summary!$AA$2:$AA21,Data_Summary!AA21)=1,Data_Summary!AA21,""))) | AK20: =IF(AJ20="","",COUNTIFS(Data_Summary!$Y$2:$Y$20001,"Coverage",Data_Summary!$AA$2:$AA$20001,AJ20)) | AM20: =IF(Data_Insight!X20="","",IF(COUNTIF(Data_Insight!$X$2:$X20,Data_Insight!X20)=1,Data_Insight!X20,"")) -> Josh (Fun Engagements) | AN20: =IF(AM20="","",COUNTIF(Data_Insight!$X$2:$X$20001,AM20)) -> 9
Q21: {=IFERROR(INDEX($AJ$2:$AJ$599,MATCH(1,($AK$2:$AK$599=R21)*(COUNTIF($Q$3:$Q20,$AJ$2:$AJ$599)=0)*($AJ$2:$AJ$599<>""),0)),"")} -> Career Visibility & Skill Roadmap | R21: =IFERROR(LARGE($AK$2:$AK$599,19),"") -> 7 | S21: =IF(Q21="","",IFERROR(R21/$B$3,0)) -> 0.023333333 | T21: {=IF(Q21="","",IFERROR(INDEX(SummaryData[Engagement Type],MATCH(TRIM(Q21),TRIM(SummaryData[Statement]),0)),""))} -> Large Connect | W21: ML Returnee Connect | X21: {=SUMPRODUCT((TRIM(RawData[Empowerment])=TRIM(W21))*1)} -> 0 | AJ21: =IF(Data_Summary!Y22<>"Coverage","",IF(Data_Summary!AA22="","",IF(COUNTIFS(Data_Summary!$Y$2:$Y22,"Coverage",Data_Summary!$AA$2:$AA22,Data_Summary!AA22)=1,Data_Summary!AA22,""))) | AK21: =IF(AJ21="","",COUNTIFS(Data_Summary!$Y$2:$Y$20001,"Coverage",Data_Summary!$AA$2:$AA$20001,AJ21)) | AM21: =IF(Data_Insight!X21="","",IF(COUNTIF(Data_Insight!$X$2:$X21,Data_Insight!X21)=1,Data_Insight!X21,"")) -> New Joiner Connect (60 Days) | AN21: =IF(AM21="","",COUNTIF(Data_Insight!$X$2:$X$20001,AM21)) -> 22
